Workbook

Sheet Case Study Description
A1: ID | B1: Participant(s) | C1: Case Study (Domains) | D1: Summary
A2: CS1 | B2: Danilo Pianini | C2: IT/Cloud Infrastructure | D2: Partition-induced collective-state divergence and oscillatory adaptation: In distributed and collective systems, uncertainties in network connectivity and system behavior can lead agents to maintain inconsistent views of the system state, causing coordination instability, oscillatory adaptation behavior, and temporary performance inefficiencies.
A3: CS2 | B3: Christos Tsigkanos | C3: Aerospace | D3: Spacecraft FDIR and Redundancy: A nanosatellite system with redundant onboard computing uses fault detection and recovery mechanisms to monitor system health and maintain operation under failures. Uncertainties related to fault detection delays, unreliable telemetry, and recovery state transitions can affect the spacecraft’s ability to safely switch modes and activate redundant components.
A4: CS3 | B4: Gabriel Moreno | C4: IT/Cloud Infrastructure | D4: Self-Adaptive RUBiS: a self-adaptive multi-tier cloud web application that dynamically adjusts resources and service quality in response to changing workloads. Uncertainties such as fluctuating request rates, tactic delays, response times, and model parameters affect the system’s ability to maintain performance and optimize resource usage.
A5: CS4 | B5: Nicolas Cardozo, Ivana Dusparic | C5: Smart City | D5: TranCity Public Transport System: TranCity is a Smart City transportation monitoring system that continuously observes buses, stations, and road conditions and dynamically adapts to changing urban environments. Multiple concurrent events and constraint violations can interact in uncertain ways, creating challenges in selecting the most effective adaptation strategy to optimize system performance.
A6: CS5 | B6: Livia Lestingi | C6: Healthcare/Robotics | D6: Human-Machine Teaming in Healthcare Robotics: A hospital service-robot scenario where a robot assists patients and medical staff by escorting patients and transporting equipment through a sequence of Healthcare tasks. The mission involves coordinated navigation and task execution, where successful completion depends on the robot reliably performing all services in a dynamic environment.
A7: CS6 | B7: Fuyuki Ishikawa | C7: Automotive | D7: Instruction-based Autonomous Driving Systems: Given the recent advancement of Vision-Language-Action models, there is active effort on autonomous driving systems that accept user instructions such as “speed up” and “move to the left lane”.
A8: CS7 | B8: Nicolas Cardozo | C8: Automotive | D8: Driving Assistant: A driving assistant system supports autonomous driving decisions on highways by detecting and responding to repeated driving behaviors. Uncertainty arising from varying environmental and vehicle conditions makes it difficult to predict and adapt to all possible driving situations and behavior combinations.
A9: CS8 | B9: Marin Litoiu | C9: IT/Cloud Infrastructure | D9: Adaptive Parallelism for LLM Serving: Modern LLM serving systems face uncertainty from highly variable workloads and unpredictable output generation, which affect memory usage, batching decisions, and latency. These uncertainties can significantly increase tail latency and become even more complex in agent-based AI systems where multiple LLMs interact and coordinate tasks.
A10: CS9 | B10: Karthik Vaidhyanathan | C10: IT/Cloud Infrastructure | D10: Agentic CloudOps: CloudOps is an AI-driven cloud management system that automates operational tasks such as resource provisioning, compliance management, and incident response. The increasing complexity of cloud environments introduces uncertainty in managing large-scale operations, requiring adaptive and autonomous decision-making mechanisms.
A11: CS10 | B11: Ivana Dusparic | C11: IT/Cloud Infrastructure | D11: Risk-Averse Constrained Reinforcement Learning: Risk-averse constrained reinforcement learning aims to learn safe decision-making policies while minimizing catastrophic failures under uncertainty. A key challenge is balancing exploration and safety, since learning about rare events requires exploration that may increase exposure to unsafe situations, often resulting in conservative or suboptimal behavior.
A12: CS11 | B12: Genaina Rodrigues | C12: Healthcare | D12: The Body Sensor Network (BSN): A Body Sensor Network for Healthcare monitoring must detect medical emergencies while respecting patient privacy preferences. Reduced monitoring capability and unreliable sensor data create uncertainty, requiring the system to make safety-critical decisions under partial observability.
... A19: CS18 | B19: Papadopoulos | C19: Robotics | D19: ROS 2 Mobile-Robot MPC Stack: A self-adaptive mobile Robotics system must maintain safety and performance under interacting uncertainties arising from imperfect physical models, dynamic environments, and software execution effects. Mitigations for one uncertainty can amplify others, creating emergent failures that cannot be predicted through isolated analyses.

Sheet Sources and Nature
A1: C | B1: ='Case Study Description'!C1 -> Case Study (Domains) | C1: Uncertainty Sources (verbatim)
A2: ='Case Study Description'!A2 -> CS1 | B2: ='Case Study Description'!C2 -> IT/Cloud Infrastructure | C2: Spatio-temporal uncertainty - environment/resources dynamic topology, partitions, temporary disconnections, varying neighborhood density. Occurrence uncertainty - resources/environment node failures, flaky join/leave, churn Behavior uncertainty - adaptation functions Some algorithms (e.g. bounded election) may amplify small topology uncertainties Measurement uncertainty (unsure) - model Propagation times and delays may induce inconsistent snapshots (the larger the snapshot area, the worse)
A3: ='Case Study Description'!A3 -> CS2 | B3: ='Case Study Description'!C3 -> Aerospace | C3: U1 Hardware Fault Occurrence Nature: Occurrence Category: Environment Managed System U2 Telemetry Accuracy Nature: Measurement Category: Resources Managed System U3 FDIR Response Latency Nature: Spatio-temporal Category: Adaptation Functions U4 Redundant Master Activation Delay Nature: Spatio-temporal Category: Resources Managed System U5 Operational Mode Estimation Nature: Belief Category: Model
A4: ='Case Study Description'!A4 -> CS3 | B4: ='Case Study Description'!C4 -> IT/Cloud Infrastructure | C4: U1. Request arrival rate: the number of requests from users arriving at the system per second Nature: measurement, behavior Category: environment, adaptation functions U2. Estimated request arrival rate: estimation of arrival rates in the near future Nature: belief Category: model U3. Service rate: the number of requests a server processes per second without contention. This cannot be directly measured at run time, it is affected by the behavior of unmodeled parts of the system (e.g., cache) and must be estimated with models. Nature: behavior, belief Category: managed system, model, adaptation functions U4. Server utilization: the percentage of time a server is busy processing requests Nature: measurement Category: resources, managed system, adaptation functions U5. Average response time: the average time it takes from the time a request arrives until its response is sent. Nature: measurement Category: adaptation functions U6. Estimated average response time: the estimated average response time for a given environment and system state. Nature: belief Category: model U7. Tactic latency: The time it takes between when a tactic is started and when its effect is produced. Nature: spatiotemporal Category: managed system, resources U8. Utility: A measure of the goodness of the performance of the system with respect to its adaptation goal. Nature: belief, measurement Category: goals
A5: ='Case Study Description'!A5 -> CS4 | B5: ='Case Study Description'!C5 -> Smart City | C5: Each uncertainty source involved in the interaction is described in terms of its: Uncertainty source nature [4]. Occurrence uncertainty: Uncertainties take place unannounced and any/all of them may take place at any time during the system execution, in different parts of the system. Behavior uncertainty: Whenever a situation is triggered, the appropriate behavior to assure continuous and correct system execution is unknown, due to the combination of situations, which are unknown beforehand Spatio-temporal uncertainty: The behavior takes place independently and unannounced in time and space. Uncertainty source category [1]. Adaptation functions: The way in which the system adapts to face specific situations is unknown Environment: The environment state in which a specific erroneous situation takes place is partially unknown Resources: The available resources to deal with a situation are unknown
A6: ='Case Study Description'!A6 -> CS5 | B6: ='Case Study Description'!C6 -> Healthcare/Robotics | C6: Human Behavior (Human-in-the-loop): Human behavior is intrinsically unpredictable. The human interacting with the robot may decide to stray from the plan (or be unable to follow it). Therefore, any model of human behavior must be either stochastic or capture this non-determinism/unpredictability in some way. Category: Environment Nature: Occurrence Human Behavior (Model Drift/Abstraction/Incompleteness): Human “behavior” is also so vast that no model can realistically cover it exhaustively. This means that a drift between the model state and the real state of the phenomenon (i.e., the real state of the human) must be always taken into account. Category: Model Nature: Behavior Sensing/AI-in-the-loop: Even if an act of human behavior is properly modeled, sensors or AI modules detecting it (for example, cameras or speech recognition modules) are inherently imperfect. Category: Adaptation Functions Nature: Measurement
A7: ='Case Study Description'!A7 -> CS6 | B7: ='Case Study Description'!C7 -> Automotive | C7: Uncertainty of traffic scenarios Occurence-Environment The operational design domain is essentially underspecified in the open world and may contain situations that have not been analyzed/argued/verified in the development time or that are out of distribution of the training data Uncertainty of user instructions Occurrence-Goals/Environment User instructions may be given that have not been analyzed/argued/verified in the development time, in terms of what instructions come at what timing Uncertainty of behavior by end-to-end black-box model Design/Behavior-Model The core behavior of the system is implemented by an end-to-end learning: intermediate data such as sensing results are in the latent space and it is not possible to precisely capture the behavior characteristics including performance limitations What driving actions are taken in a specific traffic scenario, how much they are properly interpreted and processed What reactions (follow or reject) are taken to a given instruction in a specific traffic scenario, how much they are properly interpreted and processed (others common in cyber-physical systems such as uncertainty regarding sensing and actuating)
A8: ='Case Study Description'!A8 -> CS7 | B8: ='Case Study Description'!C8 -> Automotive | C8: Uncertainty source nature [4]. Occurrence uncertainty: (Environment uncertainty) Specific situations in which uncertainties interact are unannounced (or happen independently). The points in the execution in which uncertainties come about are unpredictable. Behavior uncertainty: (Environment) Three interacting conditions from teh environment can take It is infeasible to foresee the agent behavior for all different situations that may take place. Spatio-temporal uncertainty: The behavior takes places unannounced in time and space.
A9: ='Case Study Description'!A9 -> CS8 | B9: ='Case Study Description'!C9 -> IT/Cloud Infrastructure | C9: S1. User input Unpredictable request arrival patterns Prompt content Prompt length Domain distribution (reasoning versus retrieval, e.g) S2. LLM itself Stochastic decoding Temperature sampling Output length variance Context window size LLM interactions pattern (parallel, serial, combination) S3. Environment Memory bandwidth saturation KV-cache pressure GPU contention
A10: ='Case Study Description'!A10 -> CS9 | B10: ='Case Study Description'!C10 -> IT/Cloud Infrastructure | C10: U1. LLM plan/trajectory variability: Non-deterministic reasoning changes tool choice and sequencing. Nature: behavior; Category: model/LLM, goals. U2. Instruction and policy interpretation ambiguity: Natural-language policies can be interpreted differently; constraints may be incomplete. Nature: belief/design; Category: behaviour U3. Tool Selection: Involves selecting a tool for a given task. Similar tool descriptions or overlapping capabilities cause mis-selection. Nature: belief Category: model, behaviour U4. Tool execution and error uncertainty: API failures, rate limits, partial failures; error messages may be non-diagnostic. Nature: occurrence; Category: belief/environment. U5. Memory Staleness and retrieval gaps: Stored context may be outdated; retrieval may be incomplete (low recall) even when precise. Nature: belief/behavior Category: managed system, model U6. Varying Request Arrival Rate Nature: measurement/behaviour Category: environment U7: Context Window Limitation: The bounded context window of LLM-based agents induces partial observability of system state and prior reasoning steps Nature: belief/structural Category: state, model
A11: ='Case Study Description'!A11 -> CS10 | B11: ='Case Study Description'!C11 -> IT/Cloud Infrastructure | C11: The source of uncertainty can be considered to be a mix between occurrence uncertainty and spatio-temporal uncertainty - we know that costly/catastrophic events we want to avoid can occur in the environment, but we don’t know how frequently, when or where will they occur. Uncertainty source category can be considered to be both environment and adaptation functions (agent behaviour) - we don’t know if, when, where will environmental factor that increase cost/cause catastrophic event occur, but we also do not know when will agent behave in a risky manner (as determined by its risk level, or as required to explore the environment).
A12: ='Case Study Description'!A12 -> CS11 | B12: ='Case Study Description'!C12 -> Healthcare | C12: Measurement uncertainty: Robot battery level Quantitative, continuous, probabilistic (sensor noise, estimation error) Occurrence uncertainty: Unexpected mission events (e.g., timeout, failure) → Discrete event-based, stochastic Design uncertainty: Mission model completeness → Epistemic (lack of knowledge at design time) Behavior uncertainty: Robot navigation performance under dynamic conditions → Stochastic + non-deterministic Belief uncertainty: Robot belief about environment state → Epistemic, inferential (belief-state based) Spatio-temporal uncertainty: Encountering obstacle → Spatial ambiguity + temporal unpredictability
A13: ='Case Study Description'!A13 -> CS12 | B13: ='Case Study Description'!C13 -> Robotics | C13: Measurement uncertainty: Vital signals → Quantitative, probabilistic, noisy Occurrence uncertainty: Emergency occurrence → Discrete, stochastic event uncertainty Design uncertainty: Diagnostic model adequacy → Epistemic (incomplete medical model assumptions) Behavior uncertainty: Patient movement variability → Stochastic, context-dependent Belief uncertainty: “Has the patient fallen?” → Epistemic, inferential, second-order Spatio-temporal uncertainty: Location and timing of medical event → Spatial imprecision + temporal latency.
... A19: ='Case Study Description'!A19 -> CS18 | B19: ='Case Study Description'!C19 -> Robotics | C19: U1. Parametric uncertainty (robot dynamics + contact): uncertain mass/payload, friction, wheel radius, actuator constants, slip parameters. Nature: Design uncertainty (unknown parameter values/design assumptions in the model used for decision-making). Category: Model + Managed system (the abstraction/model and the physical subsystem being controlled). U2. Timing uncertainty (compute jitter, deadline misses): variable execution time of perception (NN inference), localization, planning (graph search/sampling), and control (MPC QP solve); OS scheduling jitter; garbage collection/allocator stalls; cache effects. Nature: Spatio-temporal uncertainty (uncertainty about timing of events in the system). Category: Adaptation functions + Resources (the loop’s functions depend on compute scheduling and available CPU/GPU). U3. Delay uncertainty (sensing/actuation/communication latency): sensor pipeline latency (camera exposure + ISP + inference), time synchronization error, actuator command latency, ROS 2 DDS transport delay, Wi-Fi contention. Nature: Spatio-temporal uncertainty. Category: Adaptation functions + Resources + sometimes Environment (network conditions). U4. External / exogenous disturbances: pushes from carts/humans, floor bumps, wind gusts (loading dock), sudden slip, unmodeled contact forces during docking or manipulation. Nature: typically Behavior uncertainty (unknown/unpredictable environment dynamics) plus discrete Occurrence uncertainty for “event-like” disturbances (e.g., a sudden shove). Category: Environment + Managed system (disturbances act through the plant). U5. Concurrency uncertainty (nondeterminism in software execution): race conditions in shared state (e.g., costmap updates vs planner reads), callback interleavings, message reordering, clock skew across nodes, inconsistent snapshots (estimate/planner/controller using different “world states”). Nature: Behavior uncertainty (lack of knowledge/predictability of system behavior under concurrency). Category: Adaptation functions + Managed system (software subsystem behavior). U6. Measurement uncertainty (sensor noise + calibration drift): IMU bias, wheel odometry noise, LiDAR range noise, camera depth error, miscalibration. Nature: Measurement uncertainty (aleatory variation in measurements). Category: Adaptation functions (monitoring/sensing). U7. Environment uncertainty (scene dynamics + humans): unpredictable pedestrian motion, other robots’ policies, temporary obstacles, lighting changes. Nature: Behavior uncertainty (+ Occurrence for appearance/disappearance of obstacles). Category: Environment. U8. Resource uncertainty (energy + compute availability): battery state-of-charge only indirectly observable; GPU contention; thermal throttling. Nature: often Occurrence (availability) + Measurement (imperfect sensing of battery/thermal state). Category: Resources. U9. Goal/utility uncertainty (objective weights + trade-offs): how to weight safety vs speed vs energy, possibly changing by stakeholder/site policy (“busy hours”). Nature: Belief uncertainty (stakeholders/operators disagree/are unsure). Category: Goals. U10. Model abstraction uncertainty (map/costmap discretization, simplifications): grid resolution effects, unmodeled actuator saturation, simplified contact/friction model. Nature: Design uncertainty (modeling choices/abstractions). Category: Model.

Sheet Interaction Problem
A1: C | B1: ='Case Study Description'!C1 -> Case Study (Domains) | C1: Uncertainty Interaction Category | D1: Uncertainty Nature | E1: Abstraction Gap | F1: Impact | G1: UC-Conflict | H1: UC-Dominance | I1: UC-Augmentation | J1: UC-Independence
A2: ='Case Study Description'!A2 -> CS1 | B2: ='Case Study Description'!C2 -> IT/Cloud Infrastructure | C2: Augmentation: improving responsiveness can decrease instability/overhead under assumptions of no network segmentation. Conflict (dominant): improving responsiveness (more frequent monitoring/replanning, aggressive leadership changes) can increase instability/overhead under intermittent connectivity (more oscillations, more inconsistent plans). | D2: Heterogeneous | E2: Different abstraction levels: physical mobility/connectivity, computational fields, mission-level coordination | F2: Triggers: Environmental changes: temporary disconnections and partitions. System actions: coordination and plans changing due to segmentation. Impact scope: propagation waves. Metrics: number and overhead of replanning. Spectrum: from inefficiency to disruption. | H2: 1 | I2: 1
A3: ='Case Study Description'!A3 -> CS2 | B3: ='Case Study Description'!C3 -> Aerospace | C3: Dominance: U1 completely dominates U4; the uncertainty of the redundant master activation delay is strictly irrelevant unless a critical hardware fault actually occurs. Conflict: Mitigating U3 (FDIR Response Latency) requires assigning higher CPU scheduling priority to the active FDIRController thread, which incurs context-switching overhead that conflicts with the conservation of computing resources (related to U2). Augmentation: U1 highly augments U2; a severe hardware anomaly will intrinsically degrade the reliability of the telemetry data flowing from the compromised subsystem. | D3: Heterogeneous | E3: Low-level telemetry vs higher architectural state | F3: Trigger(s): environmental disruption (e.g., radiation). Impact scope: system-wide safe mode or failure. Metrics: link availability, telemetry preserved, downtime. Spectrum: extremely high severity. | G3: 1 | H3: 1 | I3: 1
A4: ='Case Study Description'!A4 -> CS3 | B4: ='Case Study Description'!C4 -> IT/Cloud Infrastructure | C4: Independence: From the point of view of uncertainty interaction, U1 is independent from the rest. However, it can be affected by the behavior (not the uncertainty) of the system itself (e.g., high response time may cause users to leave the system, thus reducing the arrival rate). Dominance: U1 dominates U2; U4 and U2 dominate U3; U5 and U1 dominate U8; U7 and U2 dominate U6. Augmentation: Conflict: Reducing U7 by having the system try tactics to measure their latency, increases U4, U3, U6. | D4: Homogeneous and heterogeneous interactions | E4: Different levels of abstractions | F4: Triggers: traffic increase, tactic adaptation. Impact: higher uncertainty in response time estimations. | G4: 3 | H4: 4 | J4: 1
A5: ='Case Study Description'!A5 -> CS4 | B5: ='Case Study Description'!C5 -> Smart City | C5: Independence: no uncertainty from any source affects the the uncertainty from another source Dominance: one source of uncertainty dominates the other, and reducing the uncertainty from the dominant source necessarily reduces the other. Augmentation: uncertainties highly correlated with each other (no dominance). Reduction of one of them positively affects the reduction of the other. Conflict: reduction of uncertainty from one source may increase uncertainty from another one. | D5: Heterogeneous | E5: All uncertainties at the same abstraction level | F5: Triggers: violation of monitored variables. Impact metrics: number and duration of violations, fairness. | G5: 1 | H5: 1 | I5: 1 | J5: 1
A6: ='Case Study Description'!A6 -> CS5 | B6: ='Case Study Description'!C6 -> Healthcare/Robotics | C6: Dominance: If an act of human behavior is not modeled, the model will fail to capture it even if it is probabilistic/non-deterministic: abstraction/incompleteness dominates human-in-the-loop Dominance: If an act of human behavior is not modeled, buying more reliable sensors or training more accurate AI models will not help: abstraction/incompleteness dominates sensing/AI-in-the-loop Augmentation: The more accurate the sensors/AI modules, the more accurate will be the model in aligning with human state (provided it is modeled): Triggers: human ignores robot instruction fatigue increases faster than predicted (enabling scope: specific ranges of walking speed, fatigue, controller thresholds) predictor estimates low success probability (enabling scope: mission deadline) Impact metrics: probability of completing the mission within a deadline expected fatigue level precision/recall of ML predictors Spectrum: duration: mission execution severity (consequences): mission failure, excessive fatigue, loss of trust | D6: Heterogeneous | E6: Human level, model level, ML predictor level | F6: Triggers: human ignores instruction, fatigue increases. Metrics: probability of completing mission, fatigue level. Spectrum: mission execution, failure, loss of trust. | H6: 1
A7: ='Case Study Description'!A7 -> CS6 | B7: ='Case Study Description'!C7 -> Automotive | C7: Augmentation Decreasing uncertainty of traffic scenarios and user interactions allow for increasing confidence in testing coverage and helping reducing uncertainty of black-box behavior | D7: Heterogeneous | E7: No? same level in traffic descriptions | F7: Trigger: exceptional scenario with vague instruction. Impact: crash or undesirable traffic behavior. | I7: 1
A8: ='Case Study Description'!A8 -> CS7 | B8: ='Case Study Description'!C8 -> Automotive | C8: Augmentation: uncertainties highly correlated with each other (no dominance). Reduction of one of them positively affects the reduction of the other. Conflict: reduction of uncertainty from one source may increase uncertainty from another one. | D8: Heterogeneous | E8: Same abstraction level interaction agent-environment | F8: Triggers: proximity to vehicle. Metrics: number of adaptations, violations. Spectrum: highly likely. | G8: 1 | I8: 1
A9: ='Case Study Description'!A9 -> CS8 | B9: ='Case Study Description'!C9 -> IT/Cloud Infrastructure | C9: Independence: no uncertainty from any source affects the the uncertainty from another source Dominance: one source of uncertainty dominates the other, and reducing the uncertainty from the dominant source necessarily reduces the other. Augmentation: uncertainties highly correlated with each other (no dominance). Reduction of one of them positively affects the reduction of the other. Conflict: reduction of uncertainty from one source may increase uncertainty from another one. | D9: Heterogeneous | E9: Different abstraction levels | F9: Impact described generically (trigger scope metrics spectrum) describing system performance effects. | G9: 1 | H9: 1 | I9: 1 | J9: 1
A10: ='Case Study Description'!A10 -> CS9 | B10: ='Case Study Description'!C10 -> IT/Cloud Infrastructure | C10: U7 -> U5: dominance (?) U1 -> U5: augmentation (?) U7 -> U5 -> U1: dominance + augmentation (?) | D10: Heterogeneous interactions | E10: Different abstraction levels | F10: Impact: reliability and safety, correctness, cost, sustainability impact. | H10: 1 | I10: 1
A11: ='Case Study Description'!A11 -> CS10 | B11: ='Case Study Description'!C11 -> IT/Cloud Infrastructure | C11: Uncertainty sources are in conflict; reducing uncertainty by exploring (in order to learn about frequency and/or locations of when/where uncertain events occur, further exposes the system to cost incurred by these uncertainties) | D11: Homogeneous | F11: Impact described generically (template text) | G11: 1 | H11: 1 | I11: 1
A12: ='Case Study Description'!A12 -> CS11 | B12: ='Case Study Description'!C12 -> Healthcare | C12: Battery measurement × mission continuation → Dominance (battery uncertainty dominates mission feasibility) Obstacle uncertainty × belief uncertainty → Augmentation Battery optimization × exploration behavior → Conflict | D12: Heterogeneous | E12: Different levels: sensor, world model, mission goal; | F12: Triggers: low battery, obstacle, timeout; | G12: 1 | H12: 1 | I12: 1
A13: ='Case Study Description'!A13 -> CS12 | B13: ='Case Study Description'!C13 -> Robotics | C13: Vital signal uncertainty × fall detection belief → Augmentation Signal filtering × emergency detection → Conflict Patient behavior × emergency occurrence → Augmentation | D13: Heterogeneous | E13: signal, inference, clinical goal | F13: BSN triggers abnormal signals; metrics mission success, delay, safety, false positives. | G13: 1 | I13: 2
A14: ='Case Study Description'!A14 -> CS13 | B14: ='Case Study Description'!C14 -> IT/Cloud Infrastructure | C14: Conflict: This interaction is not confined to one abstraction level. Occurrence uncertainty in the environment (U1) is transformed into measurement uncertainty in system metrics (U2). Metric variability influences belief uncertainty in adaptation decisions (U3). Decision uncertainty then affects uncertainty in goal satisfaction (U4). Alongside this transformation, conflict emerges because reducing uncertainty in one objective (e.g., improving reliability via redundancy) increases uncertainty or volatility in other objectives (e.g., cost and performance). The example therefore exhibits both cross-layer transformation and multi-objective conflict. | D14: Heterogeneous | E14: Physical, monitoring, decision, goal levels | F14: Triggers packet loss, failures. Impact reliability cost performance violations. | G14: 1
A15: ='Case Study Description'!A15 -> CS14 | B15: ='Case Study Description'!C15 -> Automotive | C15: Independence: no uncertainty from any source affects the the uncertainty from another source Dominance: one source of uncertainty dominates the other, and reducing the uncertainty from the dominant source necessarily reduces the other. Augmentation: uncertainties highly correlated with each other (no dominance). Reduction of one of them positively affects the reduction of the other. Conflict: reduction of uncertainty from one source may increase uncertainty from another one. | D15: Heterogeneous | E15: Different physical vs high level | F15: Impact generic template text. | G15: 1 | H15: 1 | I15: 1
A16: ='Case Study Description'!A16 -> CS15 | B16: ='Case Study Description'!C16 -> IT/Cloud Infrastructure | C16: Independence: no uncertainty from any source affects the uncertainty from another source N/A in this case Dominance: one source of uncertainty dominates the other, and reducing the uncertainty from the dominant source necessarily reduces the other. U1 (Incompleteness) dominates U2 (Fidelity) and U3 (AI Reliability). If key variables affecting behavior are not measured, the ST cannot accurately mirror the RT regardless of modeling precision and LLMs could have higher levels of hallucination; reducing the "completeness" uncertainty necessarily improves the fidelity of the virtual replica and could improve LLMs reliability. Augmentation: uncertainties highly correlated with each other (no dominance). Reduction of one of them positively affects the reduction of the other. U1 (Incompleteness) and U2 (Fidelity) are highly correlated since the incomplete identification of variables affect the fidelity of the model, and a low-quality model could lack relevant variables. Conflict: reduction of uncertainty from one source may increase uncertainty from another one. N/A in this case | D16: Heterogeneous | E16: Low-level telemetry to high-level AI | F16: Triggers untracked configuration. Impact DT mismatch SLA violations. | G16: 1 | H16: 2 | I16: 1 | J16: 1
A17: ='Case Study Description'!A17 -> CS16 | B17: ='Case Study Description'!C17 -> Automotive | C17: (Possible) Dominance If the resolution logic depends directly on perception confidence (e.g., “if pedestrian probability > threshold”), then reducing detection uncertainty improves decision quality. Improved perception necessarily improves conflict resolution uncertainty. Augmentation Poor visibility (fog) increases detection uncertainty. Road friction (e.g., wet surface) increases braking uncertainty. Both simultaneously increase pedestrian protection uncertainty. Reducing sensor noise (better detection) improves braking timing effectiveness. Improving braking (better actuators) reduces the impact of late detection. Conflict Reducing uncertainty in pedestrian detection (lower detection threshold, more conservative braking) may increase pedestrian safety, yet increasing ACC control uncertainty (sudden braking, violation of ACC safety distance, rear-end collision). Aggressive PP uncertainty reduction → ACC control uncertainty increases (safety may degrade). Aggressive ACC control uncertainty reduction → PP uncertainty increases (pedestrian safety degrades). Tradeoff emerges. | D17: Heterogeneous | E17: Requirements control logic feature logic perception physical | F17: Triggers pedestrian crossing ACC acceleration. Impact collision risk. | G17: 1 | H17: 1 | I17: 1
A18: ='Case Study Description'!A18 -> CS17 | B18: ='Case Study Description'!C18 -> Automotive | C18: Conflict: There is a fundamental trade-off. To reduce the uncertainty of "takeover failure" (human-side), the system prefers a longer takeover time. However, a longer window requires the system to operate/predict further into the future, which significantly increases the uncertainty regarding environmental behavior. Reducing uncertainty in one domain inevitably increases it in the other. | D18: Heterogeneous | E18: Different levels cognitive vs physical | F18: Trigger ODD boundary; metrics takeover success workload; high severity. | G18: 1
A19: ='Case Study Description'!A19 -> CS18 | B19: ='Case Study Description'!C19 -> Robotics | C19: (1) Augmentation (positive coupling): Timing jitter (U2) and delay uncertainty (U3) jointly increase effective “state staleness,” which amplifies the impact of parametric uncertainty (U1) and disturbances (U4) on closed-loop stability and safety margins. Conceptually: jitter → variable sensor age → estimator lag → controller uses an outdated/biased state; with model mismatch and disturbances, tracking error grows superlinearly. (2) Conflict (trade-off via mitigation actions): Reducing measurement uncertainty (U6) by adding sensors / increasing perception rate (more camera frames, bigger NN) increases compute load, worsening timing uncertainty (U2) and sometimes communication delay (U3). The “fix” for one uncertainty increases another. (3) Dominance (one uncertainty makes others irrelevant): In degraded lighting / heavy occlusion, environment/perception-driven uncertainty (U7 + U6) can dominate: until localization/perception becomes trustworthy, tightening dynamics parameters (U1) or fine-tuning control gains yields negligible benefit compared to restoring observability or switching to a safer operating mode. | D19: Heterogeneous | E19: Multiple abstraction levels physical software policy | F19: Triggers dense environment, mode changes. Metrics collision probability, tracking error, delays. | G19: 1 | H19: 1 | I19: 1
G20: =SUM(G2:G19) -> 16 | H20: =SUM(H2:H19) -> 17 | I20: =SUM(I2:I19) -> 15 | J20: =SUM(J2:J19) -> 4
F24: robotics+conflict | G24: =COUNTIFS($B$2:$B$19,"Robotics",$G$2:$G$19,">=1") -> 2
F25: robotics+augmentation | G25: =COUNTIFS($B$2:$B$19,"Robotics",$I$2:$I$19,">=1") -> 2
F26: robotics+dominance | G26: =COUNTIFS($B$2:$B$19,"Robotics",$H$2:$H$19,">=1") -> 1
F27: robotics+independent | G27: =COUNTIFS($B$2:$B$19,"Robotics",$J$2:$J$19,">=1") -> 0
F29: automotive+conflict | G29: =COUNTIFS($B$2:$B$19,"Automotive",$G$2:$G$19,">=1") -> 4
F30: automotive+augmentation | G30: =COUNTIFS($B$2:$B$19,"Automotive",$I$2:$I$19,">=1") -> 4
F31: automotive+dominance | G31: =COUNTIFS($B$2:$B$19,"Automotive",$H$2:$H$19,">=1") -> 2
F32: automotive+independent | G32: =COUNTIFS($B$2:$B$19,"Automotive",$J$2:$J$19,">=1") -> 0
F34: IT/Cloud Infrastructure + conflict | G34: =COUNTIFS($B$2:$B$19,"IT/Cloud Infrastructure",$G$2:$G$19,">=1") -> 5
F35: IT/Cloud Infrastructure + augmentation | G35: =COUNTIFS($B$2:$B$19,"IT/Cloud Infrastructure",$I$2:$I$19,">=1") -> 5
F36: IT/Cloud Infrastructure + dominance | G36: =COUNTIFS($B$2:$B$19,"IT/Cloud Infrastructure",$H$2:$H$19,">=1") -> 6
F37: IT/Cloud Infrastructure + independent | G37: =COUNTIFS($B$2:$B$19,"IT/Cloud Infrastructure",$J$2:$J$19,">=1") -> 3
F39: Smart City + conflict | G39: =COUNTIFS($B$2:$B$19,"*Smart*",$G$2:$G$19,">=1") -> 1
F40: Smart City +augmentation | G40: =COUNTIFS($B$2:$B$19,"*Smart*",$G$2:$G$19,">=1") -> 1
F41: Smart City + dominance | G41: =COUNTIFS($B$2:$B$19,"*Smart*",$G$2:$G$19,">=1") -> 1
F42: Smart City + independent | G42: =COUNTIFS($B$2:$B$19,"*Smart*",$G$2:$G$19,">=1") -> 1
F44: Healthcare + conflict | G44: =COUNTIFS($B$2:$B$19,"Healthcare*",$G$2:$G$19,">=1") -> 1
F45: Healthcare + augmentation | G45: =COUNTIFS($B$2:$B$19,"Healthcare*",$I$2:$I$19,">=1") -> 1
F46: Healthcare + dominance | G46: =COUNTIFS($B$2:$B$19,"Healthcare*",$H$2:$H$19,">=1") -> 2
F47: Healthcare + independent | G47: =COUNTIFS($B$2:$B$19,"Healthcare",$J$2:$J$19,">=1") -> 0
...

Sheet Solution Space
A1: C | B1: Case Study (Domains) | C1: Description | D1: Uncertainty Sources | E1: Level of Preparedness | F1: Applicability Conditions | G1: Lifecycle Stage | H1: Trade-offs | I1: Strategy
A2: CS1 | B2: IT/Cloud Infrastructure | C2: Partition-induced collective-state divergence and oscillatory adaptation: In distributed and collective systems, uncertainties in network connectivity and system behavior can lead agents to maintain inconsistent views of the system state, causing coordination instability, oscillatory adaptation behavior, and temporary performance inefficiencies. | D2: Spatio-temporal uncertainty - environment/resources dynamic topology, partitions, temporary disconnections, varying neighborhood density. Occurrence uncertainty - resources/environment node failures, flaky join/leave, churn Behavior uncertainty - adaptation functions Some algorithms (e.g. bounded election) may amplify small topology uncertainties Measurement uncertainty (unsure) - model Propagation times and delays may induce inconsistent snapshots (the larger the snapshot area, the worse) | E2: Awareness: medium - can be collectively detected. Prevention: In most cases, total prevention is not possible (environmental origin). Detectability: Yes. Representation: Yes. One idea is measuring the computational field stability. Comprehension/analyzability: Partial, currently: via simulation. On HIL/real systems, there is a tooling gap (we would need flight recording and replay). Mitigation: Possible, maybe via stability aware adaptation. | F2: Systems with no natural central coordinator nor connectivity guarantee, forcing collective decision making. | G2: Both: stress test and parameterization through simulation, collective detection and dampening must occur at runtime. | H2: Robustness vs overhead: more robustness typically implies more data to be exchanged, causing computational and network overhead. Responsiveness vs overhead: more responsiveness implies more exchanges and computation, too. Responsiveness vs stability: immediate response may cause unneeded/excessive adaptations under high churn. | I2: Detection: Collective instability fields: measure cluster churn rate, leader change rate, field convergence age, partition likelihood; Corner-case detectors. Representation: Extend aggregate programs with confidence/age annotations on shared state; represent partitions and stability regions as fields. Analysis: Simulation-driven Monte Carlo processes; adversarial corner cases. Mitigation: Hysteresis, exponential backoff, low-pass filtering, disruption prediction, partition tolerance, collective dampening.
A3: CS2 | B3: Aerospace | C3: Spacecraft FDIR and Redundancy: A nanosatellite system with redundant onboard computing uses fault detection and recovery mechanisms to monitor system health and maintain operation under failures. Uncertainties related to fault detection delays, unreliable telemetry, and recovery state transitions can affect the spacecraft’s ability to safely switch modes and activate redundant components. | D3: U1 Hardware Fault Occurrence Nature: Occurrence Category: Environment Managed System U2 Telemetry Accuracy Nature: Measurement Category: Resources Managed System U3 FDIR Response Latency Nature: Spatio-temporal Category: Adaptation Functions U4 Redundant Master Activation Delay Nature: Spatio-temporal Category: Resources Managed System U5 Operational Mode Estimation Nature: Belief Category: Model | E3: Detection: Hardware metrics are polled continuously, and non-responsive components trigger software watchdogs via the Health class. Representation: The FSM rigorously models valid transition logic within the Controller component. Mitigation: The system possesses highly structured mitigation routines executed by the FDIRController or cold redundancy handovers to the PDPU. | F3: The shared CAN bus must remain physically intact to allow the PDPU to communicate with peripheral subsystems. The non-volatile FRAM must also remain uncorrupted to supply the last known operational state variables upon reboot. | G3: Predominantly run-time (for autonomous anomaly detection and state transitions). However, mitigation strategies rely heavily on design-time component configuration and rigorous verification protocols. | H3: Utilizing active components provides excellent temporal decoupling and responsiveness but increases memory utilization and context-switching overhead. FatalHandler achieves minimal delay and overhead but sacrifices granular state management. | I3: Detection: Ping/Echo tactic utilizing software watchdogs. Analysis: Event filtering and categorization by ActiveLogger. Mitigation: State degradation governed by an FSM enforcing allowable transitions through guard functions.
A4: CS3 | B4: IT/Cloud Infrastructure | C4: Self-Adaptive RUBiS: a self-adaptive multi-tier cloud web application that dynamically adjusts resources and service quality in response to changing workloads. Uncertainties such as fluctuating request rates, tactic delays, response times, and model parameters affect the system’s ability to maintain performance and optimize resource usage. | D4: U1. Request arrival rate: the number of requests from users arriving at the system per second Nature: measurement, behavior Category: environment, adaptation functions U2. Estimated request arrival rate: estimation of arrival rates in the near future Nature: belief Category: model U3. Service rate: the number of requests a server processes per second without contention. This cannot be directly measured at run time, it is affected by the behavior of unmodeled parts of the system (e.g., cache) and must be estimated with models. Nature: behavior, belief Category: managed system, model, adaptation functions U4. Server utilization: the percentage of time a server is busy processing requests Nature: measurement Category: resources, managed system, adaptation functions U5. Average response time: the average time it takes from the time a request arrives until its response is sent. Nature: measurement Category: adaptation functions U6. Estimated average response time: the estimated average response time for a given environment and system state. Nature: belief Category: model U7. Tactic latency: The time it takes between when a tactic is started and when its effect is produced. Nature: spatiotemporal Category: managed system, resources U8. Utility: A measure of the goodness of the performance of the system with respect to its adaptation goal. Nature: belief, measurement Category: goals | E4: Field left blank. | F4: Field left blank. | G4: Field left blank. | H4: Field left blank. | I4: Field left blank.
A5: CS4 | B5: Smart Cities | C5: TranCity Public Transport System: TranCity is a Smart City transportation monitoring system that continuously observes buses, stations, and road conditions and dynamically adapts to changing urban environments. Multiple concurrent events and constraint violations can interact in uncertain ways, creating challenges in selecting the most effective adaptation strategy to optimize system performance. | D5: Each uncertainty source involved in the interaction is described in terms of its: Uncertainty source nature [4]. Occurrence uncertainty: Uncertainties take place unannounced and any/all of them may take place at any time during the system execution, in different parts of the system. Behavior uncertainty: Whenever a situation is triggered, the appropriate behavior to assure continuous and correct system execution is unknown, due to the combination of situations, which are unknown beforehand Spatio-temporal uncertainty: The behavior takes place independently and unannounced in time and space. Uncertainty source category [1]. Adaptation functions: The way in which the system adapts to face specific situations is unknown Environment: The environment state in which a specific erroneous situation takes place is partially unknown Resources: The available resources to deal with a situation are unknown | E5: Awareness: Developers are aware of the uncertainties in the systems. Prevention: Some sources of uncertainty can be foreseen but possibly not prevented. Detectability: equip agents to detect specific situations. Representation: The uncertainty cannot be modeled. Comprehension/analyzability: Depending on the uncertainty type its effect could be analyzed. Mitigation: fine grained behavior to compose into more elaborate solutions. | F5: Applicability restricted to the enabling scope of the uncertainty. So long a special situation is detected, the system will switch to a specific behavior until the system state returns to a safe state. | G5: Run-time. | H5: Detecting and mitigating an uncertainty is costly, requiring observation in multiple instances to learn the appropriate behavior. However, the solution seeks to increase fairness in the proposed correction. | I5: Detection: continuously monitoring the environment state. Representation: self-adaptation and self-organization following context-oriented programming where uncertainties are represented as first-class system objects. Analysis: unknown. Mitigation: dampen the uncertainty through corrective behavior.
A6: CS5 | B6: Healthcare/Robotics | C6: Human-Machine Teaming in Healthcare Robotics: A hospital service-robot scenario where a robot assists patients and medical staff by escorting patients and transporting equipment through a sequence of Healthcare tasks. The mission involves coordinated navigation and task execution, where successful completion depends on the robot reliably performing all services in a dynamic environment. | D6: Human Behavior (Human-in-the-loop): Human behavior is intrinsically unpredictable. The human interacting with the robot may decide to stray from the plan (or be unable to follow it). Therefore, any model of human behavior must be either stochastic or capture this non-determinism/unpredictability in some way. Category: Environment Nature: Occurrence Human Behavior (Model Drift/Abstraction/Incompleteness): Human “behavior” is also so vast that no model can realistically cover it exhaustively. This means that a drift between the model state and the real state of the phenomenon (i.e., the real state of the human) must be always taken into account. Category: Model Nature: Behavior Sensing/AI-in-the-loop: Even if an act of human behavior is properly modeled, sensors or AI modules detecting it (for example, cameras or speech recognition modules) are inherently imperfect. Category: Adaptation Functions Nature: Measurement | E6: mitigation level reached with proactive adaptation | F6: controllable factors exist; predictor model can be trained; formal model is available; time budget is sufficient for adaptation. | G6: the solution spans from design-time (training the predictor) to runtime adaptation. | H6: fast trigger detection and adaptation (between 2 and 9 seconds) but low guarantees because of AI-in-the-loop. | I6: Detection: Threshold-based trigger on predicted success probability. Representation: SHA network with stochastic transitions, MITL properties, ML regression/classification models. Analysis: Statistical Model Checking, NSGA-II multi-objective optimization, Explainable AI (PDP + LIME). Mitigation: Modify controllable factors and asynchronous formal verification.
A7: CS6 | B7: Automotive | C7: Instruction-based Autonomous Driving Systems: Given the recent advancement of Vision-Language-Action models, there is active effort on autonomous driving systems that accept user instructions such as “speed up” and “move to the left lane”. | D7: Uncertainty of traffic scenarios Occurence-Environment The operational design domain is essentially underspecified in the open world and may contain situations that have not been analyzed/argued/verified in the development time or that are out of distribution of the training data Uncertainty of user instructions Occurrence-Goals/Environment User instructions may be given that have not been analyzed/argued/verified in the development time, in terms of what instructions come at what timing Uncertainty of behavior by end-to-end black-box model Design/Behavior-Model The core behavior of the system is implemented by an end-to-end learning: intermediate data such as sensing results are in the latent space and it is not possible to precisely capture the behavior characteristics including performance limitations What driving actions are taken in a specific traffic scenario, how much they are properly interpreted and processed What reactions (follow or reject) are taken to a given instruction in a specific traffic scenario, how much they are properly interpreted and processed (others common in cyber-physical systems such as uncertainty regarding sensing and actuating) | E7: Awareness: In principle, V&V activities consider combinations of scenario factors. Prevention, detectability, representation, comprehension/analyzability, mitigation: A lot of work on the traffic scenario + behavior part, especially testing and monitoring ... We started to work on the specific aspect of user instruction ... but we have not thought of the interaction aspect yet... | F7: Field left blank. | G7: Both design time and run time solutions. | H7: Field left blank. | I7: Field left blank.
A8: CS7 | B8: Automotive | C8: Driving Assistant: A driving assistant system supports autonomous driving decisions on highways by detecting and responding to repeated driving behaviors. Uncertainty arising from varying environmental and vehicle conditions makes it difficult to predict and adapt to all possible driving situations and behavior combinations. | D8: Uncertainty source nature [4]. Occurrence uncertainty: (Environment uncertainty) Specific situations in which uncertainties interact are unannounced (or happen independently). The points in the execution in which uncertainties come about are unpredictable. Behavior uncertainty: (Environment) Three interacting conditions from teh environment can take It is infeasible to foresee the agent behavior for all different situations that may take place. Spatio-temporal uncertainty: The behavior takes places unannounced in time and space. | E8: Awareness: Developers are aware of the uncertainties. Prevention: Some sources can be foreseen but possibly not prevented. Detectability: detect specific situations. Representation: The uncertainty could be modeled. Comprehension/analyzability: Depending on uncertainty type. Mitigation: equip assistant with fine grained behavior. | F8: Restricted to the enabling scope of the uncertainty. System switches to specific behavior until it returns to a safe state. | G8: Run time. | H8: Requires observation of multiple execution instances to learn appropriate behavior; the assistant may underperform/fail while the solution is generated. | I8: Detection: continuous monitoring. Representation: context-oriented programming. Analysis: unknown. Mitigation: corrective behavior is triggered as soon as uncertainty is detected.
A9: CS8 | B9: IT/Cloud Infrastructure | C9: Adaptive Parallelism for LLM Serving: Modern LLM serving systems face uncertainty from highly variable workloads and unpredictable output generation, which affect memory usage, batching decisions, and latency. These uncertainties can significantly increase tail latency and become even more complex in agent-based AI systems where multiple LLMs interact and coordinate tasks. | D9: S1. User input Unpredictable request arrival patterns Prompt content Prompt length Domain distribution (reasoning versus retrieval, e.g) S2. LLM itself Stochastic decoding Temperature sampling Output length variance Context window size LLM interactions pattern (parallel, serial, combination) S3. Environment Memory bandwidth saturation KV-cache pressure GPU contention | E9: Field left blank. | F9: Field left blank. | G9: Field left blank. | H9: Field left blank. | I9: Not provided.
A10: CS9 | B10: IT/Cloud Infrastructure | C10: Agentic CloudOps: CloudOps is an AI-driven cloud management system that automates operational tasks such as resource provisioning, compliance management, and incident response. The increasing complexity of cloud environments introduces uncertainty in managing large-scale operations, requiring adaptive and autonomous decision-making mechanisms. | D10: U1. LLM plan/trajectory variability: Non-deterministic reasoning changes tool choice and sequencing. Nature: behavior; Category: model/LLM, goals. U2. Instruction and policy interpretation ambiguity: Natural-language policies can be interpreted differently; constraints may be incomplete. Nature: belief/design; Category: behaviour U3. Tool Selection: Involves selecting a tool for a given task. Similar tool descriptions or overlapping capabilities cause mis-selection. Nature: belief Category: model, behaviour U4. Tool execution and error uncertainty: API failures, rate limits, partial failures; error messages may be non-diagnostic. Nature: occurrence; Category: belief/environment. U5. Memory Staleness and retrieval gaps: Stored context may be outdated; retrieval may be incomplete (low recall) even when precise. Nature: belief/behavior Category: managed system, model U6. Varying Request Arrival Rate Nature: measurement/behaviour Category: environment U7: Context Window Limitation: The bounded context window of LLM-based agents induces partial observability of system state and prior reasoning steps Nature: belief/structural Category: state, model | E10: Awareness: Instrument agents with tracing of tool calls, memory queries, policy checks, and environment state snapshots. Prevention: Enforce deterministic guardrails and constrain tools to safe subsets. Detectability: using static checks, memory retrieval accuracy, and LLM-as-judge score. Representation: (blank). Comprehension/analyzability: Correlate traces with environment events and perform failure attribution. Mitigation: Fallback strategies. | F10: Not provided. | G10: Design-time and run-time. | H10: Not provided. | I10: Detection: Traces, metrics and logs that appear from the agents and the LLM scores. Representation: blank. Analysis: blank. Mitigation: not specified beyond template prompt.
A11: CS10 | B11: IT/Cloud Infrastructure | C11: Risk-Averse Constrained Reinforcement Learning: Risk-averse constrained reinforcement learning aims to learn safe decision-making policies while minimizing catastrophic failures under uncertainty. A key challenge is balancing exploration and safety, since learning about rare events requires exploration that may increase exposure to unsafe situations, often resulting in conservative or suboptimal behavior. | D11: The source of uncertainty can be considered to be a mix between occurrence uncertainty and spatio-temporal uncertainty - we know that costly/catastrophic events we want to avoid can occur in the environment, but we don’t know how frequently, when or where will they occur. Uncertainty source category can be considered to be both environment and adaptation functions (agent behaviour) - we don’t know if, when, where will environmental factor that increase cost/cause catastrophic event occur, but we also do not know when will agent behave in a risky manner (as determined by its risk level, or as required to explore the environment). | E11: Field left blank. | F11: Field left blank. | G11: Field left blank. | H11: Field left blank. | I11: Field left blank.
A12: CS11 | B12: Healthcare | C12: The Body Sensor Network (BSN): A Body Sensor Network for Healthcare monitoring must detect medical emergencies while respecting patient privacy preferences. Reduced monitoring capability and unreliable sensor data create uncertainty, requiring the system to make safety-critical decisions under partial observability. | D12: Measurement uncertainty: Robot battery level Quantitative, continuous, probabilistic (sensor noise, estimation error) Occurrence uncertainty: Unexpected mission events (e.g., timeout, failure) → Discrete event-based, stochastic Design uncertainty: Mission model completeness → Epistemic (lack of knowledge at design time) Behavior uncertainty: Robot navigation performance under dynamic conditions → Stochastic + non-deterministic Belief uncertainty: Robot belief about environment state → Epistemic, inferential (belief-state based) Spatio-temporal uncertainty: Encountering obstacle → Spatial ambiguity + temporal unpredictability | E12: Awareness: Yes. Prevention: Partial (redundancy, planning margins). Detectability: Yes (runtime monitoring). Representation: Yes (probabilistic + runtime models). Comprehension: Moderate. Mitigation: Yes (replanning, safe mode). | F12: Sufficient sensing capability; Defined safety thresholds; Adaptive control architecture. | G12: Both stages. | H12: Conservative thresholds ? safety ?, mission completion ?. Frequent replanning ? robustness ?, energy cost ?. | I12: Detection: Runtime monitoring; Threshold-based alerts. Representation: Probabilistic models; Runtime belief states. Analysis: Sensitivity analysis; Risk estimation. Mitigation: Replanning; Safe-mode activation; Energy-aware adaptation.
